<?xml version="1.0"?>
<robot xmlns:xacro="http://www.ros.org/wiki/xacro" name="motorwheel">
  <xacro:property name="pi" value="3.1415"/>

  <xacro:property name="m_m" value="0.02"/>
  <xacro:property name="m_w" value="0.02"/>
  <xacro:property name="m_h" value="0.065"/>
  <xacro:property name="m_d" value="0.02"/>
  <xacro:property name="w_m" value="0.01"/>
  <xacro:property name="w_r" value="0.0325"/>
  <xacro:property name="w_l" value="0.027"/>
  <xacro:macro name="motorwheel" params="prefix reflect">
    <link name="${prefix}_motor">
      <visual>
        <geometry>
          <box size="${m_w} ${m_h} ${m_d}"/>
        </geometry>
        <origin rpy="0 0 0" xyz="0 0 0"/>
      	<material name="yellow"/>
      </visual>
      <collision>
        <geometry>
          <box size="${m_w} ${m_h} ${m_d}"/>
        </geometry>
      </collision>
      <inertial>
        <mass value="${m_m}"/>
        <xacro:cuboid_i m="${m_m}" w="${m_w}" h="${m_h}" d="${m_d}"/>
      </inertial>
    </link>
    
    <joint name="base_to_${prefix}_motor" type="fixed">
      <parent link="base_link"/>
      <child link="${prefix}_motor"/>
      <origin xyz="${reflect*0.06} 0.01 -0.015"/>
    </joint>

    <link name="${prefix}_wheel">
      <visual>
        <geometry>
          <cylinder length="${w_l}" radius="${w_r}"/>
        </geometry>
        <origin xyz="0 0 0" rpy="0 ${pi/2} 0"/>
        <material name="black"/>
      </visual>
      <collision>
         <geometry>
           <cylinder length="${w_l}" radius="${w_r}"/>
         </geometry>
      </collision>
      <inertial>
        <mass value="${w_m}"/>
        <xacro:cylinder_i m="${w_m}" l="${w_l}" r="${w_r}"/>
      </inertial>
    </link>

    <joint name="${prefix}_motor_to_wheel" type="continuous">
      <parent link="${prefix}_motor"/>
      <child link="${prefix}_wheel"/>
      <axis xyz="1 0 0"/>
      <origin xyz="${reflect*0.025} 0.02 0"/>
    </joint>
  </xacro:macro>
</robot>
