<?xml version="1.0"?>
<robot xmlns:xacro="http://www.ros.org/wiki/xacro" name="wheel">
  <xacro:property name="pi" value="3.1415"/>

  <material name="yellow">
    <color rgba="0.8 0.8 0 1"/>
  </material>

  <material name="black">
    <color rgba="0 0 0 1"/>
  </material>

  <xacro:macro name="wheel" params="prefix reflect">
    <link name="${prefix}_motor">
      <visual>
        <geometry>
          <box size="0.02 0.065 0.02"/>
        </geometry>
        <origin rpy="0 0 0" xyz="0 0 0"/>
      	<material name="yellow"/>
      </visual>
    </link>
    
    <joint name="base_to_${prefix}_motor" type="fixed">
      <parent link="base_link"/>
      <child link="${prefix}_motor"/>
      <origin xyz="${reflect*0.06} 0.01 -0.015"/>
    </joint>

    <link name="${prefix}_wheel">
      <visual>
        <geometry>
          <cylinder length="0.027" radius="0.0325"/>
        </geometry>
        <origin xyz="0 0 0" rpy="0 ${pi/2} 0"/>
        <material name="black"/>
      </visual>
    </link>

    <joint name="${prefix}_motor_to_wheel" type="continuous">
      <parent link="${prefix}_motor"/>
      <child link="${prefix}_wheel"/>
      <axis xyz="1 0 0"/>
      <origin xyz="${reflect*0.025} 0.02 0"/>
    </joint>
  </xacro:macro>
</robot>
